This job can be monitored from: https://grafana.c3se.chalmers.se/d/gpu-job/gpu-job?var-jobid=2904503&from=1728036652000
2024-10-04 12:10:55.347219: I tensorflow/core/util/port.cc:113] oneDNN custom operations are on. You may see slightly different numerical results due to floating-point round-off errors from different computation orders. To turn them off, set the environment variable `TF_ENABLE_ONEDNN_OPTS=0`.
2024-10-04 12:10:55.384591: E external/local_xla/xla/stream_executor/cuda/cuda_dnn.cc:9261] Unable to register cuDNN factory: Attempting to register factory for plugin cuDNN when one has already been registered
2024-10-04 12:10:55.384619: E external/local_xla/xla/stream_executor/cuda/cuda_fft.cc:607] Unable to register cuFFT factory: Attempting to register factory for plugin cuFFT when one has already been registered
2024-10-04 12:10:55.385438: E external/local_xla/xla/stream_executor/cuda/cuda_blas.cc:1515] Unable to register cuBLAS factory: Attempting to register factory for plugin cuBLAS when one has already been registered
/mimer/NOBACKUP/groups/kthmech/sadanori/01_Ret180/01_velocity_yp15/sadanori/lib/python3.11/site-packages/tensorflow_addons/utils/tfa_eol_msg.py:23: UserWarning: 

TensorFlow Addons (TFA) has ended development and introduction of new features.
TFA has entered a minimal maintenance and release mode until a planned end of life in May 2024.
Please modify downstream libraries to take dependencies from other repositories in our TensorFlow community (e.g. Keras, Keras-CV, and Keras-NLP). 

For more information see: https://github.com/tensorflow/addons/issues/2807 

  warnings.warn(
2024-10-04 12:10:59.450696: I tensorflow/core/common_runtime/gpu/gpu_device.cc:1929] Created device /job:localhost/replica:0/task:0/device:GPU:0 with 38553 MB memory:  -> device: 0, name: NVIDIA A100-SXM4-40GB, pci bus id: 0000:31:00.0, compute capability: 8.0
2024-10-04 12:10:59.451354: I tensorflow/core/common_runtime/gpu/gpu_device.cc:1929] Created device /job:localhost/replica:0/task:0/device:GPU:1 with 38553 MB memory:  -> device: 1, name: NVIDIA A100-SXM4-40GB, pci bus id: 0000:4b:00.0, compute capability: 8.0
2024-10-04 12:10:59.451836: I tensorflow/core/common_runtime/gpu/gpu_device.cc:1929] Created device /job:localhost/replica:0/task:0/device:GPU:2 with 38553 MB memory:  -> device: 2, name: NVIDIA A100-SXM4-40GB, pci bus id: 0000:ca:00.0, compute capability: 8.0
2024-10-04 12:10:59.452228: I tensorflow/core/common_runtime/gpu/gpu_device.cc:1929] Created device /job:localhost/replica:0/task:0/device:GPU:3 with 38553 MB memory:  -> device: 3, name: NVIDIA A100-SXM4-40GB, pci bus id: 0000:e3:00.0, compute capability: 8.0
WARNING:absl:`lr` is deprecated in Keras optimizer, please use `learning_rate` or use the legacy optimizer, e.g.,tf.keras.optimizers.legacy.Adam.
Traceback (most recent call last):
  File "/mimer/NOBACKUP/groups/kthmech/sadanori/01_Ret180/01_velocity_yp15/train.py", line 581, in <module>
    train_history = CNN_model.fit(dataset_train,
                    ^^^^^^^^^^^^^^^^^^^^^^^^^^^^
  File "/apps/Arch/software/TensorFlow/2.15.1-foss-2023a-CUDA-12.1.1/lib/python3.11/site-packages/keras/src/utils/traceback_utils.py", line 70, in error_handler
    raise e.with_traceback(filtered_tb) from None
  File "/local/tmp.2904503/__autograph_generated_fileqgj3t4gf.py", line 15, in tf__train_function
    retval_ = ag__.converted_call(ag__.ld(step_function), (ag__.ld(self), ag__.ld(iterator)), None, fscope)
    ^^^^^
ValueError: in user code:

    File "/apps/Arch/software/TensorFlow/2.15.1-foss-2023a-CUDA-12.1.1/lib/python3.11/site-packages/keras/src/engine/training.py", line 1401, in train_function  *
        return step_function(self, iterator)
    File "/apps/Arch/software/TensorFlow/2.15.1-foss-2023a-CUDA-12.1.1/lib/python3.11/site-packages/keras/src/engine/training.py", line 1384, in step_function  **
        outputs = model.distribute_strategy.run(run_step, args=(data,))
    File "/apps/Arch/software/TensorFlow/2.15.1-foss-2023a-CUDA-12.1.1/lib/python3.11/site-packages/keras/src/engine/training.py", line 1373, in run_step  **
        outputs = model.train_step(data)
    File "/apps/Arch/software/TensorFlow/2.15.1-foss-2023a-CUDA-12.1.1/lib/python3.11/site-packages/keras/src/engine/training.py", line 1150, in train_step
        y_pred = self(x, training=True)
    File "/apps/Arch/software/TensorFlow/2.15.1-foss-2023a-CUDA-12.1.1/lib/python3.11/site-packages/keras/src/utils/traceback_utils.py", line 70, in error_handler
        raise e.with_traceback(filtered_tb) from None
    File "/apps/Arch/software/TensorFlow/2.15.1-foss-2023a-CUDA-12.1.1/lib/python3.11/site-packages/keras/src/engine/input_spec.py", line 298, in assert_input_compatibility
        raise ValueError(

    ValueError: Input 0 of layer "model" is incompatible with the layer: expected shape=(None, 3, 432, 432), found shape=(None, 3, 496, 496)

