This job can be monitored from: https://grafana.c3se.chalmers.se/d/gpu-job/gpu-job?var-jobid=2772009&from=1726229662000
2024-09-13 14:14:24.947373: I tensorflow/core/util/port.cc:113] oneDNN custom operations are on. You may see slightly different numerical results due to floating-point round-off errors from different computation orders. To turn them off, set the environment variable `TF_ENABLE_ONEDNN_OPTS=0`.
2024-09-13 14:14:24.984954: E external/local_xla/xla/stream_executor/cuda/cuda_dnn.cc:9261] Unable to register cuDNN factory: Attempting to register factory for plugin cuDNN when one has already been registered
2024-09-13 14:14:24.984984: E external/local_xla/xla/stream_executor/cuda/cuda_fft.cc:607] Unable to register cuFFT factory: Attempting to register factory for plugin cuFFT when one has already been registered
2024-09-13 14:14:24.985825: E external/local_xla/xla/stream_executor/cuda/cuda_blas.cc:1515] Unable to register cuBLAS factory: Attempting to register factory for plugin cuBLAS when one has already been registered
2024-09-13 14:14:28.299810: I tensorflow/core/common_runtime/gpu/gpu_device.cc:1929] Created device /job:localhost/replica:0/task:0/device:GPU:0 with 38553 MB memory:  -> device: 0, name: NVIDIA A100-SXM4-40GB, pci bus id: 0000:31:00.0, compute capability: 8.0
Traceback (most recent call last):
  File "/mimer/NOBACKUP/groups/kthmech/sadanori/01_Ret180/01_velocity_yp15/CNN-predict_1.py", line 780, in <module>
    init_model = tf.keras.models.load_model(
                 ^^^^^^^^^^^^^^^^^^^^^^^^^^^
  File "/apps/Arch/software/TensorFlow/2.15.1-foss-2023a-CUDA-12.1.1/lib/python3.11/site-packages/keras/src/saving/saving_api.py", line 262, in load_model
    return legacy_sm_saving_lib.load_model(
           ^^^^^^^^^^^^^^^^^^^^^^^^^^^^^^^^
  File "/apps/Arch/software/TensorFlow/2.15.1-foss-2023a-CUDA-12.1.1/lib/python3.11/site-packages/keras/src/utils/traceback_utils.py", line 70, in error_handler
    raise e.with_traceback(filtered_tb) from None
  File "/apps/Arch/software/TensorFlow/2.15.1-foss-2023a-CUDA-12.1.1/lib/python3.11/site-packages/keras/src/saving/legacy/save.py", line 234, in load_model
    raise IOError(
OSError: No file or directory found at /mimer/NOBACKUP/groups/kthmech/argb/02_VE/n25/01_velocity_yp15/.logs/NN_WallReconfluct1TF2_3NormIn-3Out_1-15_432x432_Ret180_lr0.001_decay20drop0.5_relu-1705416965/model.ckpt.0050.hdf5
